This is a testharness.js-based test.
Harness Error. harness_status.status = 1 , harness_status.message = Traceback (most recent call last):\n  File "C:\\b\\s\\w\\ir\\third_party\\wpt_tools\\wpt\\tools\\wptrunner\\wptrunner\\executors\\base.py", line 773, in process_action\n    action_handler = self.actions[action]\n                     ~~~~~~~~~~~~^^^^^^^^\nKeyError: 'bidi.session.subscribe'\n\nThe above exception was the direct cause of the following exception:\n\nTraceback (most recent call last):\n  File "C:\\b\\s\\w\\ir\\third_party\\wpt_tools\\wpt\\tools\\wptrunner\\wptrunner\\executors\\executorwebdriver.py", line 1085, in run_func\n    self.result = True, self.func(self.protocol, self.url, self.timeout)\n                        ^^^^^^^^^^^^^^^^^^^^^^^^^^^^^^^^^^^^^^^^^^^^^^^^\n  File "C:\\b\\s\\w\\ir\\third_party\\wpt_tools\\wpt\\tools\\wptrunner\\wptrunner\\executors\\executorwebdriver.py", line 1181, in do_testharness\n    raw_results = protocol.testdriver.run(url, self.script_resume, test_window)\n                  ^^^^^^^^^^^^^^^^^^^^^^^^^^^^^^^^^^^^^^^^^^^^^^^^^^^^^^^^^^^^^\n  File "C:\\b\\s\\w\\ir\\third_party\\wpt_tools\\wpt\\tools\\wptrunner\\wptrunner\\executors\\executorwebdriver.py", line 681, in run\n    done, rv = handler(test_driver_message)\n               ^^^^^^^^^^^^^^^^^^^^^^^^^^^^\n  File "C:\\b\\s\\w\\ir\\third_party\\wpt_tools\\wpt\\tools\\wptrunner\\wptrunner\\executors\\base.py", line 761, in __call__\n    return callback(url, payload)\n           ^^^^^^^^^^^^^^^^^^^^^^\n  File "C:\\b\\s\\w\\ir\\third_party\\wpt_tools\\wpt\\tools\\wptrunner\\wptrunner\\executors\\base.py", line 775, in process_action\n    raise ValueError(f"Unknown action {action}") from e\nValueError: Unknown action bidi.session.subscribe\n
Harness: the test ran to completion.

